<?xml version="1.0" ?>
<robot name="thien_robot">
  <!-- Define color -->
  <material name="green">
    <color rgba="0 0.5 0 1"/>
  </material>
  <material name="blue">
    <color rgba="0 0 0.5 1"/>
  </material>
  <material name="grey">
    <color rgba="0.5 0.5 0.5 1"/>
  </material>
  <material name="red">
    <color rgba="1 0 0 0.7"/>
  </material>
  <material name="dark">
    <color rgba="0.5 0.5 0.5 1"/>
  </material>
  <!-- Define links -->
  <link name="base_footprint"/>
  <link name="base_link">
    <visual>
      <geometry>
        <box size="0.3 0.19 0.12"/>
      </geometry>
      <origin rpy="0 0 0" xyz="0 0 0.06"/>
      <material name="green"/>
    </visual>
    <collision>
      <geometry>
        <box size="0.3 0.19 0.12"/>
      </geometry>
      <origin rpy="0 0 0" xyz="0 0 0.06"/>
      <material name="green"/>
    </collision>
    <inertial>
      <origin rpy="0 0 0" xyz="0 0 0.06"/>
      <mass value="5.0"/>
      <inertia ixx="0.0435" ixy="0" ixz="0" iyy="0.05254166666666667" iyz="0" izz="0.02104166666666667"/>
    </inertial>
  </link>
  <link name="left_wheel_link">
    <visual>
      <geometry>
        <cylinder length="0.025" radius="0.05"/>
      </geometry>
      <origin rpy="1.5707963267948966 0 0" xyz="0 0 0"/>
      <material name="blue"/>
    </visual>
    <collision>
      <geometry>
        <cylinder length="0.025" radius="0.05"/>
      </geometry>
      <origin rpy="1.5707963267948966 0 0" xyz="0 0 0"/>
    </collision>
    <inertial>
      <origin rpy="1.5707963267948966 0 0" xyz="0 0 0"/>
      <mass value="1.0"/>
      <inertia ixx="0.0006770833333333335" ixy="0" ixz="0" iyy="0.0006770833333333335" iyz="0" izz="0.0012500000000000002"/>
    </inertial>
  </link>
  <link name="right_wheel_link">
    <visual>
      <geometry>
        <cylinder length="0.025" radius="0.05"/>
      </geometry>
      <origin rpy="1.5707963267948966 0 0" xyz="0 0 0"/>
      <material name="blue"/>
    </visual>
    <collision>
      <geometry>
        <cylinder length="0.025" radius="0.05"/>
      </geometry>
      <origin rpy="1.5707963267948966 0 0" xyz="0 0 0"/>
    </collision>
    <inertial>
      <origin rpy="1.5707963267948966 0 0" xyz="0 0 0"/>
      <mass value="1.0"/>
      <inertia ixx="0.0006770833333333335" ixy="0" ixz="0" iyy="0.0006770833333333335" iyz="0" izz="0.0012500000000000002"/>
    </inertial>
  </link>

  <link name="caster_wheel_link">
    <visual>
      <geometry>
        <sphere radius="0.025"/>
      </geometry>
      <origin rpy="0 0 0" xyz="0 0 0"/>
      <material name="red"/>
    </visual>
    <collision>
      <geometry>
        <sphere radius="0.025"/>
      </geometry>
      <origin rpy="0 0 0" xyz="0 0 0"/>
    </collision>
    <inertial>
      <origin rpy="0 0 0" xyz="0 0 0"/>
      <mass value="5.0"/>
      <inertia ixx="0.0012500000000000002" ixy="0" ixz="0" iyy="0.0012500000000000002" iyz="0" izz="0.0012500000000000002"/>
    </inertial>
  </link>
  <!-- Define joints -->
  <joint name="base_joint" type="fixed">
    <parent link="base_footprint"/>
    <child link="base_link"/>
    <origin rpy="0 0 0" xyz="0 0 0.05"/>
  </joint>
  <joint name="base_right_wheel_joint" type="continuous">
    <parent link="base_link"/>
    <child link="right_wheel_link"/>
    <origin rpy="0 0 0" xyz="-0.075 -0.1075 0"/>
    <axis xyz="0 1 0"/>
  </joint>
  <joint name="base_left_wheel_joint" type="continuous">
    <parent link="base_link"/>
    <child link="left_wheel_link"/>
    <origin rpy="0 0 0" xyz="-0.075 0.1075 0"/>
    <axis xyz="0 1 0"/>
  </joint>
  <joint name="base_caster_wheel_joint" type="fixed">
    <parent link="base_link"/>
    <child link="caster_wheel_link"/>
    <origin rpy="0 0 0" xyz="0.1 0 -0.025"/>
    <axis xyz="0 0 1"/>
  </joint>
  <!-- Include lidar -->
  <!-- <link name="laser_link">
    <visual>
      <geometry>
        <mesh filename="file:///home/thien123/ROS2WS/robocon_ws/install/robot_description/share/robot_description/mesh/sensors/lds.stl" scale="0.001 0.001 0.001"/>
      </geometry>
      <origin rpy="0 0 0" xyz="0 0 0.01925"/>
      <material name="grey"/>
    </visual>
    <collision>
      <geometry>
        <cylinder length="0.039" radius="0.077"/>
      </geometry>
      <origin rpy="0 0 0" xyz="0 0 0.01925"/>
      <material name="grey"/>
    </collision>
  </link>
  <joint name="laser_joint" type="fixed">
    <parent link="base_link"/>
    <child link="laser_link"/>
    <origin rpy="0 0 0" xyz="0 0 0.12"/>
  </joint>
   -->
  <link name="camera_link">
    <visual>
      <geometry>
        <box size="0.01 0.1 0.05"/>
      </geometry>
      <material name="grey"/>
    </visual>
    <collision>
      <geometry>
        <box size="0.01 0.1 0.05"/>
      </geometry>
    </collision>
    <inertial>
      <origin rpy="0 0 0" xyz="0 0 0"/>
      <mass value="0.1"/>
      <inertia ixx="2.166666666666667e-05" ixy="0" ixz="0" iyy="8.416666666666668e-05" iyz="0" izz="0.00010416666666666669"/>
    </inertial>
  </link>
  <joint name="base_camera_joint" type="fixed">
    <parent link="base_link"/>
    <child link="camera_link"/>
    <origin rpy="0 0 0" xyz="0.155 0 0.06"/>
  </joint>
  <ros2_control name="bkr_robot" type="system">
  <hardware>
    <plugin>bkrobotics_hardware_interface/BkrRobotHardware</plugin>
    <param name="left_wheel_name">base_left_wheel_joint</param>
    <param name="right_wheel_name">base_right_wheel_joint</param>
    <!-- <param name="device">/dev/ttyUSB0</param> -->
    <param name="device">can0</param>
    <param name="baud_rate">500000</param>
    <param name="timeout_ms">1000</param>
    <param name="wheel_diameter">100</param>
    <param name="pid_p">10</param>
    <param name="pid_i">0</param>
    <param name="pid_d">1</param>
    <param name="enc_counts_per_rev">4000</param>
  </hardware>
  
  <joint name="base_left_wheel_joint">
    <command_interface name="velocity"/>
    <state_interface name="position"/>
    <state_interface name="velocity"/>
  </joint>
  
  <joint name="base_right_wheel_joint">
    <command_interface name="velocity"/>
    <state_interface name="position"/>
    <state_interface name="velocity"/>
  </joint>
</ros2_control>
</robot>
